Workbook

Sheet Sentences
A1: sentence_id | B1: CG_sentence_normalized | C1: SMG_sentence | D1: line_no | E1: notes | F1: notes from others
A2: cg_001 | B2: Δυστυχώς πάνω σε τούντο θέμαν εν κατέχω πολλές πληροφοριές , λόγω του ότι τζ̆αι ο παππούς μου τζ̆αι η γιαγιά μου που την πλευρά του παπά μου , δηλαδή στην Κύπρο , επεθάναν πριν γεννηθώ . | C2: Δυστυχώς πάνω σε τούτο το θέμα δεν κατέχω πολλές πληροφορίες , λόγω του ότι και ο παππούς μου και η γιαγιά μου από την πλευρά του μπαμπά μου , δηλαδή στην Κύπρο , πέθαναν πριν γεννηθώ . | D2: 2 | F2: ΣΑ: ΟΚ, κανονικά οι αιτιατικές "πλευράν" και "Κύπρον" ήθελαν τελικό νι (είχε ξεφύγει αυτό).
A3: cg_002 | B3: Εεε ... Οι πιο μεγάλοι της κοινότητας μου συνήθως μουρμουρούν για τους μιτσ̆ιούς ότι εν σέβουνται , ότι εν’ ττεμπέληες ... | C3: Εεε ... Οι πιο μεγάλοι της κοινότητας μου συνήθως μουρμουράνε για τους μικρούς ότι δεν σέβονται , ότι είναι τεμπέληδες ... | D3: 3
A4: cg_003 | B4: Νομίζω στην κοινότηταν μου οι πιο μιάλοι εν έχουν κάποιαν συσχέτισην ή κάποιαν σχέσην με τες πιο μιτσ̆ιές γενιές . | C4: Νομίζω στην κοινότητα μου οι πιο μεγάλοι δεν έχουν κάποια συσχέτιση ή κάποια σχέση με τις πιο μικρές γενιές. | D4: 5
A5: cg_004 | B5: Νομίζω ότι οι πιο μιτσ̆ιές γενιές διδάσκουνται παραπάνω που το ίντερνετ τζ̆αι όι που τους μεγαλλύττερους . | C5: Νομίζω ότι οι πιο μικρές γενιές διδάσκονται παραπάνω από το ίντερνετ και όχι από τους μεγαλύτερους. | D5: 8
A6: cg_005 | B6: Το πιο δυνατόν καιρικόν φαινόμενον που έζησα εν- εν’ οι καύσωνες της Κύπρου , τα καλοτζ̆αίρκα , ειδικά τζ̆είνος ο Ιούλιος . | C6: Το πιο δυνατό καιρικό φαινόμενο που έζησα είναι - είναι οι καύσωνες της Κύπρου , τα καλοκαίρια , ειδικά εκείνος ο Ιούλιος . | D6: 12
A7: cg_006 | B7: Το πιο δυνατόν καιρικόν φαινόμενον που έζησα πρέπει να 'ταν κανένας σεισμός . | C7: Το πιο δυνατό καιρικό φαινόμενο που έζησα πρέπει να ήταν κανένας σεισμός. | D7: 15
A8: cg_007 | B8: Εν έζησα κάποιον ... ιδιαίτερα δυνατόν καιρικόν φαινόμενον στην ζωή μου . | C8: Δεν έζησα κάποιο ... ιδιαίτερα δυνατό καιρικό φαινόμενο στη ζωή μου. | D8: 18
A9: cg_008 | B9: Το όνομαν μου , Σάρα , σημαίνει πριγκίπισσα στα εβραϊκά τζ̆αι εφκάλαν με έτσι γιατί άρεσκεν πάρα πολλά του παπά μου . | C9: Το όνομα μου, Σάρα, σημαίνει πριγκίπισσα στα εβραϊκά και με έβγαλαν έτσι γιατί άρεσε πάρα πολύ στον μπαμπά μου . | D9: 22
A10: cg_009 | B10: Το όνομαν Βασιλική έσ̆ει σχέσην με την βασιλείαν τζ̆αι συγκεκριμένα με την γυναίκαν που έσ̆ει βασιλικήν καταγωγήν . | C10: Το όνομα Βασιλική έχει σχέση με τη βασιλεία και συγκεκριμένα με την γυναίκα που έχει βασιλική καταγωγή . | D10: 24
A11: cg_010 | B11: Το όνομαν μου σημαίνει θεά της σοφίας τζ̆αι του στρατηγικού πολέμου . | C11: Το όνομα μου σημαίνει θεά της σοφίας και του στρατηγικού πολέμου . | D11: 25
A12: cg_011 | B12: Δυστυχώς εν ακούω ούτε κυπριακήν ούτε ελληνικήν μουσικήν για να μπορώ να πω κάποιον παράδειγμαν . | C12: Δυστυχώς δεν ακούω ούτε κυπριακή ούτε ελληνική μουσική για να μπορώ να πω κάποιο παράδειγμα . | D12: 31
A13: cg_012 | B13: Ξέρω έναν κυπριακόν τραούδιν , το Ασ̆ερόμπασμαν , αλλά εν θθυμούμαι τους στίχους του τζ̆αι λογικά εν θα τους ελαλούσα καλά έτσι τζ̆’ αλλιώς . | C13: Ξέρω ένα κυπριακό τραγούδι , το Ασερόμπασμα , αλλά δεν θυμάμαι τους στίχους του και λογικά δεν θα τους λαλούσα καλά έτσι κι αλλιώς . | D13: 37
A14: cg_013 | B14: Εν ι-ξέρω ούλλα τα λόγια κάποιου συγκεκριμμένου τραουθκιού . | C14: Δεν ξέρω όλα τα λόγια κάποιου συγκεκριμένου τραγουδιού . | D14: 39
... A42: cg_041 | B42: Πιστεύκω ότι άμαν είσαι λλίον εγκρατής , μπορείς να έσ̆εις την ίδιαν ψυχαγωγίαν , ή τζ̆αι καλλύττερην , πιο οικονομικά . | C42: Πιστεύω ότι αν είσαι λίγο εγκρατής , μπορείς να έχεις την ίδια ψυχαγωγία , ή και καλύτερη , πιο οικονομικά . | D42: 275
A43: cg_042 | B43: Αν είχα πολλά λεφτά εννά αγόραζα έναν νησίν τζ̆αι να πάω να μείνω τζ̆ειαμαί τζ̆αι να είμαι μόνη μου πά’ στο νησίν με τους σ̆σ̆ύλλους μου . | C43: Αν είχα πολλά λεφτά θα αγόραζα ένα νησί και θα πήγαινα να μείνω εκεί και θα ήμουν μόνη μου στο νησί με τους σκύλους μου . | D43: 268 | E43: πά' στο νησίν -> στο νησί (όχι πάνω στο νησί)
A44: cg_043 | B44: Εννά ήθελα πάρα πολλά να επισκευτώ τες χώρες της Μέσης Ανατολής , ειδικά τες Αραβικές χώρες , ε τούτες που τωρά εν μπορούμεν να επισκεφτούμεν γιατί εκαταστραφήκαν λόγω πολέμου . | C44: Θα ήθελα πάρα πολύ να επισκεφτώ τις χώρες της Μέσης Ανατολής , ειδικά τις Αραβικές χώρες , αυτές που τώρα δεν μπορούμε να επισκεφτούμε γιατί καταστράφηκαν λόγω πολέμου . | D44: 279
A45: cg_044 | B45: Οι θερμοκρασίες του καλοτζ̆αιρκού όταν ήμουν μιτσ̆ιά σε σχέσην με τωρά ήταν πολλά πιο χαμηλές , σίουρα εν ήταν αισθητή η πυρά τόσον πολλά . | C45: Οι θερμοκρασίες του καλοκαιριού όταν ήμουν μικρή σε σχέση με τώρα ήταν πιο χαμηλές , σίγουρα δεν ήταν αισθητή η ζέστη τόσο πολύ . | D45: 304 | E45: κομμένη
A46: cg_045 | B46: Σε σχέσην που τότε που ήμασταν πιο μιτσ̆ιοί , τωρά οι καλοτζ̆αιρινές θερμοκρασίες εν' πολλά πιο ψηλές , τζ̆αι γεννικά εν' πολλή παραπάνω πυρά τζ̆αι πολλή παραπάνω υγρασία . | C46: Σε σχέση με τότε που ήμασταν πιο μικροί , τώρα οι καλοκαιρινές θερμοκρασίες είναι πολύ πιο ψηλές , και γενικά είναι πολύς παραπάνω ο καύσωνας και πολλή παραπάνω η υγρασία . | D46: 307 | E46: κομμένη
A47: cg_046 | B47: Παλιόττερα έρκετουν πολλά πιο σπάνια , τα τελευταία χρόνια όμως ζ̆ιούμεν μαζίν της . | C47: Παλιότερα ερχόταν πολύ πιο σπάνια , τα τελευταία χρόνια όμως ζούμε μαζί της . | D47: 312
A48: cg_047 | B48: Συνήθως εεεμ βρεθούμαστεν σε σπίθκια , ε ή που εννά μαειρέψω εγώ ή κάποιος άλλος που τους φίλους . | C48: Συνήθως εεεμ βρισκόμαστε σε σπίτια , όπου ή θα μαγειρέψω εγώ ή κάποιος άλλος από τους φίλους . | D48: 315
A49: cg_048 | B49: Που το σούππερμαρκετ συνήθως αγοράζω τα πιο βασικά που εν' ψωμίν , τυρίν , κανέναν αλλαντικόν , λαχανικά , φρούτα , κρέας . | C49: Από το σουπερμάρκετ συνήθως αγοράζω τα πιο βασικά που είναι ψωμί , τυρί , κανένα αλλαντικό , λαχανικά , φρούτα , κρέας .
A50: cg_049 | B50: Νομίζω τα θκιαβάσματα των τελικών εν' τα πιο αγχωτικά , επειδή εν τα επήα τόσον καλά σ τες ενδιάμεσες . | C50: Νομίζω τα διαβάσματα των τελικών είναι τα πιο αγχωτικά , επειδή δεν τα πήγα τόσο καλά στις ενδιάμεσες . | D50: 338
A51: cg_050 | B51: Έχω πάρα πολλούς αγαπημένους μουσικούς ε ο καθένας φκάλλει διαφορετικήν μουσικήν οπόταν εν' λλίον δύσκολον να θκιαλέξω τον αγαπημένον μου που ούλλους . | C51: Έχω πάρα πολλούς αγαπημένους μουσικούς και ο καθένας βγάζει διαφορετική μουσική οπότε είναι λίγο δύσκολο να διαλέξω τον αγαπημένο μου από όλους . | D51: 354
A52: cg_051 | B52: Θθυμούμαι που την εθώρουν που ’μουν μωρόν , τζ̆αι ακόμα θωρώ την άμαν εννά τύχει τζ̆αι εννά την έβρω στην τηλεόρασην . | C52: Θυμάμαι που την έβλεπα όταν ήμουν μωρό , και ακόμα τη βλέπω άμα τύχει και τη βρω στην τηλεόραση . | D52: 359
A53: cg_052 | B53: Εν ι-ξέρω αν ποττέ επαρακολούθησα κάποιαν ταινίαν κυπριακού κινηματογράφου . | C53: Δεν ξέρω αν ποτέ παρακολούθησα κάποια ταινία κυπριακού κινηματογράφου . | D53: 365
A54: cg_053 | B54: Με τόσα εκατομμύρια γαλαξίες τζ̆αι τόσα δισεκατομμύρια αστέρκα , εν’ σχεδόν βέβαιον ότι τζ̆αι κάπου αλλού εννά αναπτύχθηκεν κάποιου είδους ανώττερη νοημοσύνη . | C54: Με τόσα εκατομμύρια γαλαξίες και τόσα δισεκατομμύρια αστέρια , είναι σχεδόν βέβαιο ότι και κάπου αλλού θα αναπτύχθηκε κάποιου είδους ανώτερη νοημοσύνη . | D54: 373
A55: cg_054 | B55: Πιάννεις τηλέφωνον τον γιατρόν τζ̆αι βάλλει σε όποτε έσ̆ει κενόν . | C55: Παίρνεις τηλέφωνο το γιατρό και σε βάζει όποτε έχει κενό . | D55: 382
A56: cg_055 | B56: Έναν που τα κύρια θέματα στην ενσωμάτωσην της τεχνολογίας εν' ότι πολλά μεγάλον ποσοστόν του προσωπικού των σχολείων εν ι-ξέρει πώς να χρησιμοποιά την τεχνολογίαν . | C56: Ένα από τα κύρια θέματα στην ενσωμάτωση της τεχνολογίας είναι ότι πολύ μεγάλο ποσοστό του προσωπικού των σχολείων δεν ξέρει πώς να χρησιμοποιεί την τεχνολογία . | D56: 386
A57: cg_056 | B57: Που ’μουν μιτσής επήαιννα μπάσκετ , αλλά μετά που τα πολλά τα θκιαβάσματα εν είχα το τσ̆ανς να συνεχίσω . | C57: Όταν ήμουν μικρός πήγαινα μπάσκετ , αλλά μετά από τα πολλά διαβάσματα δεν είχα την ευκαιρία να συνεχίσω . | D57: 400
A58: cg_057 | B58: Αν είχα ποττέ παιθκιά εννά τους ελαλούσα πάντα να προσπαθούν τζ̆αι να βάλλουν τον καλλύττερον τους εαυτόν σε ό,τι κάμουν τζ̆αι να μεν τα βάλλουν ποττέ κάτω . | C58: Αν είχα ποτέ παιδιά θα τους έλεγα πάντα να προσπαθούν να βάζουν τον καλύτερό τους εαυτό σε ό,τι κάνουν και να μην τα βάζουν ποτέ κάτω . | D58: 403
A59: cg_058 | B59: Συνήθως οι πλείστοι στην νεολαίαν κάμνουσιν αγορές μαζίν με το κινητόν τζ̆αι κυρίως κάρτες . | C59: Συνήθως οι περισσότεροι στη νεολαία κάνουν αγορές με το κινητό και κυρίως κάρτες . | D59: 413
A60: cg_059 | B60: Οι πιερωμές στην χώραν μου γίνουνται παραπάνω με κάρτες τζαι κινητά παρά με μετρητά . | C60: Οι πληρωμές στη χώρα μου γίνονται περισσότερο με κάρτες και κινητά παρά με μετρητά . | D60: 420
A61: cg_060 | B61: Που ήμουν μιτσής στες διακοπές επήαιννα κάθε μέραν κολύμπιν με μάσκαν τζ̆αι άρεσκεν μου να θωρώ την ζωήν κάτω που το νερόν . | C61: Όταν ήμουν μικρός στις διακοπές πήγαινα κάθε μέρα για κολύμπι με μάσκα και μου άρεσε να βλέπω τη ζωή κάτω από το νερό . | D61: 430
... A64: cg_063 | B64: Είμαι κατά της διανομής λεφτών σε ζηθκιάνους γιατί πολλοί απατεώνες εκμεταλλεύκουνται τον ανθρώπινον πόνον για να φκάλουν ριάλλια . | C64: Είμαι κατά της διανομής λεφτών σε ζητιάνους γιατί πολλοί απατεώνες εκμεταλλεύονται τον ανθρώπινο πόνο για να βγάλουν λεφτά . | D64: 461
A65: cg_064 | B65: Πιστεύκω ότι στην Κύπρον η πιο πολλή κοινωνική βοήθεια έρκεται που τους ανθρώπους . | C65: Πιστεύω ότι στην Κύπρο η πιο πολύ κοινωνική βοήθεια έρχεται από τους ανθρώπους . | D65: 457 | E65: "οι (βοήθεια)": ορθογραφικό λάθος ; | F65: ΣΑ: ναι.
A66: cg_065 | B66: Επειδή η δουλειά μου εν' σε υπόγειον , είμαι συνηθισμένος στο να μεν έχω σήμαν κατά τες ώρες εργασίας . | C66: Επειδή η δουλειά μου είναι σε υπόγειο , είμαι συνηθισμένος στο να μην έχω σήμα κατά τις ώρες εργασίας . | D66: 494
A67: cg_066 | B67: Όμως όταν σχολάννω τζ̆αι φεύκω που τον τόπον εργασίας μου , το σήμαν ξανάρκεται τζ̆αι εν έχω κανέναν πρόβλημαν . | C67: Όμως όταν σχολάω και φεύγω από το χώρο εργασίας μου , το σήμα ξανάρχεται και δεν έχω κανένα πρόβλημα . | D67: 494
A68: cg_067 | B68: Περπατώ πάρα πολλά μες στην πολην , προτιμώ το που οποιονδήποτε άλλον μέσον μεταφοράς . | C68: Περπατώ πάρα πολύ μες στην πόλη , το προτιμώ από οποιοδήποτε άλλο μέσο μεταφοράς . | D68: 499
A69: cg_068 | B69: Σήμμερα εν ι-ξέρω αν μαθαίννουν μόνον τούτες τες γλώσσες ή αν έσ̆ει τζ̆’ άλλες γλώσσες σαν επιλογήν . | C69: Σήμερα δεν ξέρω αν μαθαίνουν μόνο αυτές τις γλώσσες ή αν έχει κι άλλες γλώσσες σαν επιλογή . | D69: 264
...

Sheet Tokens
A1: sentence_id | B1: variant | C1: token_1 | D1: token_2 | E1: token_3 | F1: token_4 | G1: token_5 | H1: token_6 | I1: token_7 | J1: token_8 | K1: token_9 | L1: token_10 | M1: token_11 | N1: token_12 | O1: token_13 | P1: token_14 | Q1: token_15 | R1: token_16 | S1: token_17 | T1: token_18 | U1: token_19 | V1: token_20 | W1: token_21 | X1: token_22 | Y1: token_23 | Z1: token_24 | AA1: token_25 | AB1: token_26 | AC1: token_27 | AD1: token_28 | AE1: token_29 | AF1: token_30 | AG1: token_31 | AH1: token_32 | AI1: token_33 | AJ1: token_34 | AK1: token_35 | AL1: token_36 | AM1: token_37 | AN1: token_38 | AO1: token_39 | AP1: token_40
A2: cg_001 | B2: CG | C2: {=IF(B2="CG", _xlfn.TEXTSPLIT(_xlfn.XLOOKUP(A2, Sentences!A:A, Sentences!B:B), " "), "")} -> Δυστυχώς | D2: πάνω | E2: σε | F2: τούντο | G2: θέμαν | H2: εν | I2: κατέχω | J2: πολλές | K2: πληροφοριές | L2: , | M2: λόγω | N2: του | O2: ότι | P2: τζ̆αι | Q2: ο | R2: παππούς | S2: μου | T2: τζ̆αι | U2: η | V2: γιαγιά | W2: μου | X2: που | Y2: την | Z2: πλευρά | AA2: του | AB2: παπά | AC2: μου | AD2: , | AE2: δηλαδή | AF2: στην | AG2: Κύπρο | AH2: , | AI2: επεθάναν | AJ2: πριν | AK2: γεννηθώ | AL2: .
A3: cg_001 | B3: SMG | C3: Δυστυχώς | D3: πάνω | E3: σε | F3: τούτο το | G3: θέμα | H3: δεν | I3: κατέχω | J3: πολλές | K3: πληροφορίες | L3: , | M3: λόγω | N3: του | O3: ότι | P3: και | Q3: ο | R3: παππούς | S3: μου | T3: και | U3: η | V3: γιαγιά | W3: μου | X3: από | Y3: την | Z3: πλευρά | AA3: του | AB3: παπά | AC3: μου | AD3: , | AE3: δηλαδή | AF3: στην | AG3: Κύπρο | AH3: , | AI3: πέθαναν | AJ3: πριν | AK3: γεννηθώ | AL3: .
A4: cg_002 | B4: CG | C4: {=IF(B4="CG", _xlfn.TEXTSPLIT(_xlfn.XLOOKUP(A4, Sentences!A:A, Sentences!B:B), " "), "")} -> Εεε | D4: ... | E4: Οι | F4: πιο | G4: μεγάλοι | H4: της | I4: κοινότητας | J4: μου | K4: συνήθως | L4: μουρμουρούν | M4: για | N4: τους | O4: μιτσ̆ιούς | P4: ότι | Q4: εν | R4: σέβουνται | S4: , | T4: ότι | U4: εν’ | V4: ττεμπέληες | W4: ...
A5: cg_002 | B5: SMG | C5: Εεε | D5: ... | E5: Οι | F5: πιο | G5: μεγάλοι | H5: της | I5: κοινότητας | J5: μου | K5: συνήθως | L5: μουρμουρούν | M5: για | N5: τους | O5: μιτσιούς | P5: ότι | Q5: δεν | R5: σέβονται | S5: , | T5: ότι | U5: είναι | V5: ττεμπέληδες | W5: ...
A6: cg_003 | B6: CG | C6: {=IF(B6="CG", _xlfn.TEXTSPLIT(_xlfn.XLOOKUP(A6, Sentences!A:A, Sentences!B:B), " "), "")} -> Νομίζω | D6: στην | E6: κοινότηταν | F6: μου | G6: οι | H6: πιο | I6: μιάλοι | J6: εν | K6: έχουν | L6: κάποιαν | M6: συσχέτισην | N6: ή | O6: κάποιαν | P6: σχέσην | Q6: με | R6: τες | S6: πιο | T6: μιτσ̆ιές | U6: γενιές | V6: .
A7: cg_003 | B7: SMG | C7: Νομίζω | D7: στην | E7: κοινότητα | F7: μου | G7: οι | H7: πιο | I7: μιάλοι | J7: δεν | K7: έχουν | L7: κάποια | M7: συσχέτιση | N7: ή | O7: κάποια | P7: σχέση | Q7: με | R7: τες | S7: πιο | T7: μιτσιές | U7: γενιές | V7: .
A8: cg_004 | B8: CG | C8: {=IF(B8="CG", _xlfn.TEXTSPLIT(_xlfn.XLOOKUP(A8, Sentences!A:A, Sentences!B:B), " "), "")} -> Νομίζω | D8: ότι | E8: οι | F8: πιο | G8: μιτσ̆ιές | H8: γενιές | I8: διδάσκουνται | J8: παραπάνω | K8: που | L8: το | M8: ίντερνετ | N8: τζ̆αι | O8: όι | P8: που | Q8: τους | R8: μεγαλλύττερους | S8: .
A9: cg_004 | B9: SMG | C9: Νομίζω | D9: ότι | E9: οι | F9: πιο | G9: μιτσιές | H9: γενιές | I9: διδάσκονται | J9: παραπάνω | K9: από | L9: το | M9: ίντερνετ | N9: και | O9: όχι | P9: από | Q9: τους | R9: μεγαλύτερους | S9: .
A10: cg_005 | B10: CG | C10: {=IF(B10="CG", _xlfn.TEXTSPLIT(_xlfn.XLOOKUP(A10, Sentences!A:A, Sentences!B:B), " "), "")} -> Το | D10: πιο | E10: δυνατόν | F10: καιρικόν | G10: φαινόμενον | H10: που | I10: έζησα | J10: εν- | K10: εν’ | L10: οι | M10: καύσωνες | N10: της | O10: Κύπρου | P10: , | Q10: τα | R10: καλοτζ̆αίρκα | S10: , | T10: ειδικά | U10: τζ̆είνος | V10: ο | W10: Ιούλιος | X10: .
A11: cg_005 | B11: SMG | C11: Το | D11: πιο | E11: δυνατό | F11: καιρικό | G11: φαινόμενο | H11: που | I11: έζησα | J11: είναι- | K11: είναι | L11: οι | M11: καύσωνες | N11: της | O11: Κύπρου | P11: , | Q11: τα | R11: καλοτζαίρια | S11: , | T11: ειδικά | U11: εκείνος | V11: ο | W11: Ιούλιος | X11: .
A12: cg_006 | B12: CG | C12: {=IF(B12="CG", _xlfn.TEXTSPLIT(_xlfn.XLOOKUP(A12, Sentences!A:A, Sentences!B:B), " "), "")} -> Το | D12: πιο | E12: δυνατόν | F12: καιρικόν | G12: φαινόμενον | H12: που | I12: έζησα | J12: πρέπει | K12: να | L12: 'ταν | M12: κανένας | N12: σεισμός | O12: .
A13: cg_006 | B13: SMG | C13: Το | D13: πιο | E13: δυνατό | F13: καιρικό | G13: φαινόμενο | H13: που | I13: έζησα | J13: πρέπει | K13: να | L13: ταν | M13: κανένας | N13: σεισμός | O13: .
A14: cg_007 | B14: CG | C14: {=IF(B14="CG", _xlfn.TEXTSPLIT(_xlfn.XLOOKUP(A14, Sentences!A:A, Sentences!B:B), " "), "")} -> Εν | D14: έζησα | E14: κάποιον | F14: ... | G14: ιδιαίτερα | H14: δυνατόν | I14: καιρικόν | J14: φαινόμενον | K14: στην | L14: ζωή | M14: μου | N14: .
A15: cg_007 | B15: SMG | C15: Δεν | D15: έζησα | E15: κάποιο | F15: ... | G15: ιδιαίτερα | H15: δυνατό | I15: καιρικό | J15: φαινόμενο | K15: στη | L15: ζωή | M15: μου | N15: .
A16: cg_008 | B16: CG | C16: {=IF(B16="CG", _xlfn.TEXTSPLIT(_xlfn.XLOOKUP(A16, Sentences!A:A, Sentences!B:B), " "), "")} -> Το | D16: όνομαν | E16: μου | F16: , | G16: Σάρα | H16: , | I16: σημαίνει | J16: πριγκίπισσα | K16: στα | L16: εβραϊκά | M16: τζ̆αι | N16: εφκάλαν | O16: με | P16: έτσι | Q16: γιατί | R16: άρεσκεν | S16: πάρα | T16: πολλά | U16: του | V16: παπά | W16: μου | X16: .
A17: cg_008 | B17: SMG | C17: Το | D17: όνομα | E17: μου | F17: , | G17: Σάρα | H17: , | I17: σημαίνει | J17: πριγκίπισσα | K17: στα | L17: εβραϊκά | M17: και | N17: φκάλαν | O17: με | P17: έτσι | Q17: γιατί | R17: άρεσκε | S17: πάρα | T17: πολύ | U17: του | V17: παπά | W17: μου | X17: .
A18: cg_009 | B18: CG | C18: {=IF(B18="CG", _xlfn.TEXTSPLIT(_xlfn.XLOOKUP(A18, Sentences!A:A, Sentences!B:B), " "), "")} -> Το | D18: όνομαν | E18: Βασιλική | F18: έσ̆ει | G18: σχέσην | H18: με | I18: την | J18: βασιλείαν | K18: τζ̆αι | L18: συγκεκριμένα | M18: με | N18: την | O18: γυναίκαν | P18: που | Q18: έσ̆ει | R18: βασιλικήν | S18: καταγωγήν | T18: .
A19: cg_009 | B19: SMG | C19: Το | D19: όνομα | E19: Βασιλική | F19: έχει | G19: σχέση | H19: με | I19: την | J19: βασιλεία | K19: και | L19: συγκεκριμένα | M19: με | N19: την | O19: γυναίκα | P19: που | Q19: έχει | R19: βασιλική | S19: καταγωγή | T19: .
A20: cg_010 | B20: CG | C20: {=IF(B20="CG", _xlfn.TEXTSPLIT(_xlfn.XLOOKUP(A20, Sentences!A:A, Sentences!B:B), " "), "")} -> Το | D20: όνομαν | E20: μου | F20: σημαίνει | G20: θεά | H20: της | I20: σοφίας | J20: τζ̆αι | K20: του | L20: στρατηγικού | M20: πολέμου | N20: .
A21: cg_010 | B21: SMG | C21: Το | D21: όνομα | E21: μου | F21: σημαίνει | G21: θεά | H21: της | I21: σοφίας | J21: και | K21: του | L21: στρατηγικού | M21: πολέμου | N21: .
A22: cg_011 | B22: CG | C22: {=IF(B22="CG", _xlfn.TEXTSPLIT(_xlfn.XLOOKUP(A22, Sentences!A:A, Sentences!B:B), " "), "")} -> Δυστυχώς | D22: εν | E22: ακούω | F22: ούτε | G22: κυπριακήν | H22: ούτε | I22: ελληνικήν | J22: μουσικήν | K22: για | L22: να | M22: μπορώ | N22: να | O22: πω | P22: κάποιον | Q22: παράδειγμαν | R22: .
A23: cg_011 | B23: SMG | C23: Δυστυχώς | D23: δεν | E23: ακούω | F23: ούτε | G23: κυπριακή | H23: ούτε | I23: ελληνική | J23: μουσική | K23: για | L23: να | M23: μπορώ | N23: να | O23: πω | P23: κάποιο | Q23: παράδειγμα | R23: .
A24: cg_012 | B24: CG | C24: {=IF(B24="CG", _xlfn.TEXTSPLIT(_xlfn.XLOOKUP(A24, Sentences!A:A, Sentences!B:B), " "), "")} -> Ξέρω | D24: έναν | E24: κυπριακόν | F24: τραούδιν | G24: , | H24: το | I24: Ασ̆ερόμπασμαν | J24: , | K24: αλλά | L24: εν | M24: θθυμούμαι | N24: τους | O24: στίχους | P24: του | Q24: τζ̆αι | R24: λογικά | S24: εν | T24: θα | U24: τους | V24: ελαλούσα | W24: καλά | X24: έτσι | Y24: τζ̆’ | Z24: αλλιώς | AA24: .
A25: cg_012 | B25: SMG | C25: Ξέρω | D25: ένα | E25: κυπριακό | F25: τραούδι | G25: , | H25: το | I25: Ασερόμπασμα | J25: , | K25: αλλά | L25: δεν | M25: θθυμάμαι | N25: τους | O25: στίχους | P25: του | Q25: και | R25: λογικά | S25: δεν | T25: θα | U25: τους | V25: λαλούσα | W25: καλά | X25: έτσι | Y25: κι | Z25: αλλιώς | AA25: .
A26: cg_013 | B26: CG | C26: {=IF(B26="CG", _xlfn.TEXTSPLIT(_xlfn.XLOOKUP(A26, Sentences!A:A, Sentences!B:B), " "), "")} -> Εν | D26: ι-ξέρω | E26: ούλλα | F26: τα | G26: λόγια | H26: κάποιου | I26: συγκεκριμμένου | J26: τραουθκιού | K26: .
A27: cg_013 | B27: SMG | C27: Δεν | D27: ξέρω | E27: όλα | F27: τα | G27: λόγια | H27: κάποιου | I27: συγκεκριμμένου | J27: τραουθκιού | K27: .
A28: cg_014 | B28: CG | C28: {=IF(B28="CG", _xlfn.TEXTSPLIT(_xlfn.XLOOKUP(A28, Sentences!A:A, Sentences!B:B), " "), "")} -> Νναι | D28: ξέρω | E28: να | F28: οδηγώ | G28: τζ̆αι | H28: είμαι | I28: τζ̆αι | J28: περήφανη | K28: ότι | L28: μπορώ | M28: να | N28: οδηγήσω | O28: ούλλα | P28: τ’ | Q28: αυτοκίνητα | R28: , | S28: όποτε | T28: αν | U28: χρειαστεί | V28: να | W28: πάει | X28: έναν | Y28: αυτοκίνητον | Z28: κάπου | AA28: , | AB28: πιάννουν | AC28: με | AD28: εμέναν | AE28: τηλέφωνον | AF28: .
A29: cg_014 | B29: SMG | C29: Ναι | D29: ξέρω | E29: να | F29: οδηγώ | G29: και | H29: είμαι | I29: και | J29: περήφανη | K29: που | L29: μπορώ | M29: να | N29: οδηγήσω | O29: όλα | P29: τα | Q29: αυτοκίνητα | R29: , | S29: οπότέ | T29: αν | U29: χρειαστεί | V29: να | W29: πάει | X29: ένα | Y29: αυτοκίνητο | Z29: κάπου | AA29: , | AB29: πιάννουν | AC29: με | AD29: εμένα | AE29: τηλέφωνο | AF29: .
A30: cg_015 | B30: CG | C30: {=IF(B30="CG", _xlfn.TEXTSPLIT(_xlfn.XLOOKUP(A30, Sentences!A:A, Sentences!B:B), " "), "")} -> Νναι | D30: ξέρω | E30: να | F30: οδηγώ | G30: , | H30: όμως | I30: το | J30: μόνον | K30: πράμαν | L30: που | M30: μπορώ | N30: να | O30: οδηγώ | P30: εν' | Q30: το | R30: αυτόματον | S30: αυτοκίνητον | T30: , | U30: τίποτε | V30: άλλον | W30: .
A31: cg_015 | B31: SMG | C31: Ναι | D31: ξέρω | E31: να | F31: οδηγώ | G31: , | H31: όμως | I31: το | J31: μόνο | K31: πράγμα | L31: που | M31: μπορώ | N31: να | O31: οδηγώ | P31: είναι | Q31: το | R31: αυτόματο | S31: αυτοκίνητο | T31: , | U31: τίποτε | V31: άλλο | W31: .
A32: cg_016 | B32: CG | C32: {=IF(B32="CG", _xlfn.TEXTSPLIT(_xlfn.XLOOKUP(A32, Sentences!A:A, Sentences!B:B), " "), "")} -> Ξέρω | D32: να | E32: οδηγώ | F32: , | G32: έχω | H32: άδειαν | I32: οδήγησης | J32: που | K32: τα | L32: δεκαεννιά | M32: μου | N32: .
A33: cg_016 | B33: SMG | C33: Ξέρω | D33: να | E33: οδηγώ | F33: , | G33: έχω | H33: άδεια | I33: οδήγησης | J33: από | K33: τα | L33: δεκαεννιά | M33: μου | N33: .
A34: cg_017 | B34: CG | C34: {=IF(B34="CG", _xlfn.TEXTSPLIT(_xlfn.XLOOKUP(A34, Sentences!A:A, Sentences!B:B), " "), "")} -> Τα | D34: οχήματα | E34: που | F34: οδήγησα | G34: εν’ | H34: το | I34: αυτοκίνητον | J34: , | K34: τράχτορ | L34: τζ̆αι | M34: μοτοσικλέτταν | N34: .
A35: cg_017 | B35: SMG | C35: Τα | D35: οχήματα | E35: που | F35: οδήγησα | G35: είναι | H35: το | I35: αυτοκίνητο | J35: , | K35: τράχτορ | L35: και | M35: μοτοσικλέτα | N35: .
A36: cg_018 | B36: CG | C36: {=IF(B36="CG", _xlfn.TEXTSPLIT(_xlfn.XLOOKUP(A36, Sentences!A:A, Sentences!B:B), " "), "")} -> Πραγματικά | D36: εν | E36: ι-ξέρω | F36: κατά | G36: πόσον | H36: οι | I36: τράπεζες | J36: όντως | K36: κρατούν | L36: τα | M36: λεφτά | N36: ασφαλισμένα | O36: .
A37: cg_018 | B37: SMG | C37: Πραγματικά | D37: δεν | E37: ξέρω | F37: κατά | G37: πόσον | H37: οι | I37: τράπεζες | J37: όντως | K37: κρατούν | L37: τα | M37: λεφτά | N37: ασφαλισμένα | O37: .
A38: cg_019 | B38: CG | C38: {=IF(B38="CG", _xlfn.TEXTSPLIT(_xlfn.XLOOKUP(A38, Sentences!A:A, Sentences!B:B), " "), "")} -> Ε | D38: ... | E38: Οι | F38: τράπεζες | G38: υποτίθεται | H38: ότι | I38: τωρά | J38: εγγυούνται | K38: σου | L38: μέχρι | M38: εκατόν | N38: σ̆ιλιάες | O38: ευρώ | P38: στες | Q38: καταθέσεις | R38: σου | S38: , | T38: τζ̆αι | U38: τούτον | V38: ήρτεν | W38: μετά | X38: που | Y38: ... | Z38: νομίζω | AA38: αν | AB38: δεν | AC38: κάμνω | AD38: λάθος | AE38: εν’ | AF38: ευρωπαϊκή | AG38: νομοθεσία | AH38: τούτη | AI38: .
A39: cg_019 | B39: SMG | C39: Ε | D39: ... | E39: Οι | F39: τράπεζες | G39: υποτίθεται | H39: ότι | I39: τώρα | J39: εγγυούνται | K39: σου | L39: μέχρι | M39: εκατό | N39: χιλιάδες | O39: ευρώ | P39: στις | Q39: καταθέσεις | R39: σου | S39: , | T39: και | U39: τούτο | V39: ήρθε | W39: μετά | X39: που | Y39: ... | Z39: νομίζω | AA39: αν | AB39: δεν | AC39: κάνω | AD39: λάθος | AE39: είναι | AF39: ευρωπαϊκή | AG39: νομοθεσία | AH39: τούτη | AI39: .
A40: cg_020 | B40: CG | C40: {=IF(B40="CG", _xlfn.TEXTSPLIT(_xlfn.XLOOKUP(A40, Sentences!A:A, Sentences!B:B), " "), "")} -> Ε | D40: ... | E40: Απ΄ | F40: όσον | G40: ξέρω | H40: για | I40: τα | J40: συστήματα | K40: που | L40: έχουν | M40: οι | N40: τράπεζες | O40: για | P40: προστασίαν | Q40: γεννικά | R40: έχουν | S40: συναγερμούς | T40: , | U40: κκάμερες | V40: , | W40: χρηματοκιβώτια | X40: .
...
